Workbook

Sheet Tulokset
A2: OTTELU | C2: TULOS | D2: AleksiTo | E2: p
A3: Otteluohjelma laadittu Chat GPT:llä, ajankohdissa virheitä | D3: Omat veikkaukset tähän sarak- keeseen
A4: Lohkovaihe
A5: LOHKO A
A6: to 11.6 klo 19:00 | B6: MEX-RSA | D6: 2-0 | E6: =IF(EXACT($C6,D6),3,IF($C6=0,0,IF(SIGN((LEFT($C6,1))-(RIGHT($C6,1)))=SIGN((LEFT(D6,1))-(RIGHT(D6,1))),1,0)))
A7: to 11.6 klo 22:00 | B7: KOR-CZE | C7: 2-1 | D7: 1-1 | E7: =IF(EXACT($C7,D7),3,IF($C7=0,0,IF(SIGN((LEFT($C7,1))-(RIGHT($C7,1)))=SIGN((LEFT(D7,1))-(RIGHT(D7,1))),1,0)))
A8: ti 16.6 klo 21:00 | B8: MEX-KOR | C8: 0-2 | D8: 1-1 | E8: =IF(EXACT($C8,D8),3,IF($C8=0,0,IF(SIGN((LEFT($C8,1))-(RIGHT($C8,1)))=SIGN((LEFT(D8,1))-(RIGHT(D8,1))),1,0)))
A9: ti 16.6 klo 00:00 | B9: CZE-RSA | C9: 1-0 | D9: 2-1 | E9: =IF(EXACT($C9,D9),3,IF($C9=0,0,IF(SIGN((LEFT($C9,1))-(RIGHT($C9,1)))=SIGN((LEFT(D9,1))-(RIGHT(D9,1))),1,0)))
A10: su 21.6 klo 18:00 | B10: RSA-KOR | D10: 0-2 | E10: =IF(EXACT($C10,D10),3,IF($C10=0,0,IF(SIGN((LEFT($C10,1))-(RIGHT($C10,1)))=SIGN((LEFT(D10,1))-(RIGHT(D10,1))),1,0)))
A11: su 21.6 klo 18:00 | B11: CZE-MEX | D11: 1-2 | E11: =IF(EXACT($C11,D11),3,IF($C11=0,0,IF(SIGN((LEFT($C11,1))-(RIGHT($C11,1)))=SIGN((LEFT(D11,1))-(RIGHT(D11,1))),1,0)))
A12: LOHKO B
A13: pe 12.6 klo 19:00 | B13: CAN-BIH | D13: 1-1 | E13: =IF(EXACT($C13,D13),3,IF($C13=0,0,IF(SIGN((LEFT($C13,1))-(RIGHT($C13,1)))=SIGN((LEFT(D13,1))-(RIGHT(D13,1))),1,0)))
A14: pe 12.6 klo 22:00 | B14: QAT-SUI | D14: 0-2 | E14: =IF(EXACT($C14,D14),3,IF($C14=0,0,IF(SIGN((LEFT($C14,1))-(RIGHT($C14,1)))=SIGN((LEFT(D14,1))-(RIGHT(D14,1))),1,0)))
A15: ke 17.6 klo 21:00 | B15: CAN-QAT | D15: 2-0 | E15: =IF(EXACT($C15,D15),3,IF($C15=0,0,IF(SIGN((LEFT($C15,1))-(RIGHT($C15,1)))=SIGN((LEFT(D15,1))-(RIGHT(D15,1))),1,0)))
A16: ke 17.6 klo 00:00 | B16: SUI-BIH | D16: 1-0 | E16: =IF(EXACT($C16,D16),3,IF($C16=0,0,IF(SIGN((LEFT($C16,1))-(RIGHT($C16,1)))=SIGN((LEFT(D16,1))-(RIGHT(D16,1))),1,0)))
A17: ma 22.6 klo 21:00 | B17: SUI-CAN | D17: 2-1 | E17: =IF(EXACT($C17,D17),3,IF($C17=0,0,IF(SIGN((LEFT($C17,1))-(RIGHT($C17,1)))=SIGN((LEFT(D17,1))-(RIGHT(D17,1))),1,0)))
A18: ma 22.6 klo 21:00 | B18: BIH-QAT | D18: 2-1 | E18: =IF(EXACT($C18,D18),3,IF($C18=0,0,IF(SIGN((LEFT($C18,1))-(RIGHT($C18,1)))=SIGN((LEFT(D18,1))-(RIGHT(D18,1))),1,0)))
A19: LOHKO C
A20: la 13.6 klo 19:00 | B20: BRA-MAR | D20: 1-1 | E20: =IF(EXACT($C20,D20),3,IF($C20=0,0,IF(SIGN((LEFT($C20,1))-(RIGHT($C20,1)))=SIGN((LEFT(D20,1))-(RIGHT(D20,1))),1,0)))
A21: la 13.6 klo 22:00 | B21: HAI-SCO | D21: 1-2 | E21: =IF(EXACT($C21,D21),3,IF($C21=0,0,IF(SIGN((LEFT($C21,1))-(RIGHT($C21,1)))=SIGN((LEFT(D21,1))-(RIGHT(D21,1))),1,0)))
A22: to 18.6 klo 21:00 | B22: SCO-MAR | D22: 1-2 | E22: =IF(EXACT($C22,D22),3,IF($C22=0,0,IF(SIGN((LEFT($C22,1))-(RIGHT($C22,1)))=SIGN((LEFT(D22,1))-(RIGHT(D22,1))),1,0)))
A23: to 18.6 klo 21:00 | B23: BRA-HAI | D23: 3-0 | E23: =IF(EXACT($C23,D23),3,IF($C23=0,0,IF(SIGN((LEFT($C23,1))-(RIGHT($C23,1)))=SIGN((LEFT(D23,1))-(RIGHT(D23,1))),1,0)))
A24: ti 23.6 klo 21:00 | B24: SCO-BRA | D24: 0-2 | E24: =IF(EXACT($C24,D24),3,IF($C24=0,0,IF(SIGN((LEFT($C24,1))-(RIGHT($C24,1)))=SIGN((LEFT(D24,1))-(RIGHT(D24,1))),1,0)))
A25: ti 23.6 klo 21:00 | B25: MAR-HAI | D25: 2-0 | E25: =IF(EXACT($C25,D25),3,IF($C25=0,0,IF(SIGN((LEFT($C25,1))-(RIGHT($C25,1)))=SIGN((LEFT(D25,1))-(RIGHT(D25,1))),1,0)))
A26: LOHKO D
A27: pe 12.6 klo 22:00 | B27: USA-PAR | D27: 2-1 | E27: =IF(EXACT($C27,D27),3,IF($C27=0,0,IF(SIGN((LEFT($C27,1))-(RIGHT($C27,1)))=SIGN((LEFT(D27,1))-(RIGHT(D27,1))),1,0)))
A28: pe 12.6 klo 19:00 | B28: AUS-TUR | D28: 1-2 | E28: =IF(EXACT($C28,D28),3,IF($C28=0,0,IF(SIGN((LEFT($C28,1))-(RIGHT($C28,1)))=SIGN((LEFT(D28,1))-(RIGHT(D28,1))),1,0)))
A29: ke 17.6 klo 21:00 | B29: USA-AUS | D29: 2-0 | E29: =IF(EXACT($C29,D29),3,IF($C29=0,0,IF(SIGN((LEFT($C29,1))-(RIGHT($C29,1)))=SIGN((LEFT(D29,1))-(RIGHT(D29,1))),1,0)))
A30: ke 17.6 klo 21:00 | B30: TUR-PAR | D30: 2-1 | E30: =IF(EXACT($C30,D30),3,IF($C30=0,0,IF(SIGN((LEFT($C30,1))-(RIGHT($C30,1)))=SIGN((LEFT(D30,1))-(RIGHT(D30,1))),1,0)))
A31: ma 22.6 klo 21:00 | B31: TUR-USA | D31: 1-1 | E31: =IF(EXACT($C31,D31),3,IF($C31=0,0,IF(SIGN((LEFT($C31,1))-(RIGHT($C31,1)))=SIGN((LEFT(D31,1))-(RIGHT(D31,1))),1,0)))
A32: ma 22.6 klo 21:00 | B32: PAR-AUS | D32: 1-1 | E32: =IF(EXACT($C32,D32),3,IF($C32=0,0,IF(SIGN((LEFT($C32,1))-(RIGHT($C32,1)))=SIGN((LEFT(D32,1))-(RIGHT(D32,1))),1,0)))
A33: LOHKO E
A34: la 13.6 klo 19:00 | B34: GER-CUR | D34: 3-0 | E34: =IF(EXACT($C34,D34),3,IF($C34=0,0,IF(SIGN((LEFT($C34,1))-(RIGHT($C34,1)))=SIGN((LEFT(D34,1))-(RIGHT(D34,1))),1,0)))
A35: la 13.6 klo 22:00 | B35: ICV-ECU | D35: 0-1 | E35: =IF(EXACT($C35,D35),3,IF($C35=0,0,IF(SIGN((LEFT($C35,1))-(RIGHT($C35,1)))=SIGN((LEFT(D35,1))-(RIGHT(D35,1))),1,0)))
A36: to 18.6 klo 21:00 | B36: GER-ICV | D36: 2-1 | E36: =IF(EXACT($C36,D36),3,IF($C36=0,0,IF(SIGN((LEFT($C36,1))-(RIGHT($C36,1)))=SIGN((LEFT(D36,1))-(RIGHT(D36,1))),1,0)))
A37: to 18.6 klo 21:00 | B37: ECU-CUR | D37: 2-0 | E37: =IF(EXACT($C37,D37),3,IF($C37=0,0,IF(SIGN((LEFT($C37,1))-(RIGHT($C37,1)))=SIGN((LEFT(D37,1))-(RIGHT(D37,1))),1,0)))
A38: ti 23.6 klo 21:00 | B38: CUR-ICV | D38: 0-2 | E38: =IF(EXACT($C38,D38),3,IF($C38=0,0,IF(SIGN((LEFT($C38,1))-(RIGHT($C38,1)))=SIGN((LEFT(D38,1))-(RIGHT(D38,1))),1,0)))
A39: ti 23.6 klo 21:00 | B39: ECU-GER | D39: 0-2 | E39: =IF(EXACT($C39,D39),3,IF($C39=0,0,IF(SIGN((LEFT($C39,1))-(RIGHT($C39,1)))=SIGN((LEFT(D39,1))-(RIGHT(D39,1))),1,0)))
A40: LOHKO F
A41: su 14.6 klo 18:00 | B41: NED-JPN | D41: 2-1 | E41: =IF(EXACT($C41,D41),3,IF($C41=0,0,IF(SIGN((LEFT($C41,1))-(RIGHT($C41,1)))=SIGN((LEFT(D41,1))-(RIGHT(D41,1))),1,0)))
...

Sheet Säännöt&Ohjeet
B1: OSALLISTUMINEN
B2: 1. Ilmoittautuminen: Ke 10.6. klo 16.00 mennessä --> 30 EUR maksettu Mobile Pay 0458500205 tai tilisiirto FI28 4405 0010 3120 42
B3: 2. Ke 10.6. klo 23:59 mennessä oman täytetyn Excelin toimittaminen Jypelle (upload OneDrive-kansioon tai Email jype.multanen@gmail.com
B5: Pisteet:
B6: 1. Lohkovaihe
B7: - Oikea tulos = 3p
B8: - Väärä tulos, mutta voittaja tai tasapeli veikattu oikein = 1p
B9: - Väärä veikkaus (ei auta vaikka vain toisen joukkueen maalit olisi oikein) = 0 p
B10: 2. Lohkovaiheen sikajengi (8p)
B11: Lohkovaiheessa eniten keltaisia ja punaisia kortteja saanut joukkue. Lasketaan niin että lohkopeleissä keltaisista korteista 1 p, kahdesta keltaisesta tullut punainen 2 p ja suora punainen 3 p. Tulos katsotaan UEFA:n tilastosta, jos ristiriitoja. Jos useammalla joukkueella sama määrä, niin kaikille oikeille veikanneille 4 pistettä.
B12: 3. Maalintekijä (1p per maali).
B13: Saat veikata tähän ketä tahansa yhtä pelaajaa. Saat 1 p per tämän pelaajan koko kisoissa tekemä maali.
... B19: - Finaalin voittaja = 30p lisää.
B21: Voitonjako | D21: pelaajaa | E21: panos/hlö | F21: POTTI
D22: 15 | E22: 30 | F22: =D22*E22
B23: 1. = 70% | F23: =F22*0.7*1
B24: 2. = 20% | F24: =F22*0.2
B25: 3. = 10% | F25: =F22*0.1
B26: Tasatilanteessa osuus jaetaan tasan olevien pelaajien kesken.
B27: Esim: Kaksi pelaajaa jaetulla ykkössijalla: Molemmat saavat (70+20)/2 = 45%. Seuraavaksi paras 10% tai jos useampia jaetaan heidän kesken.
B28: Esim: Kolme tai useampi pelaaja jaetulla ykkössijalla: Koko potti jaetaan näiden kesken.
B29: Esim: Yksi voittaja, kaksi tai useampi pelaaja jaetulla kakkossijalla. Voittajalle 70%, kakkossijan jakajille jaetaan loppuosa 30%, eli 15% kummallekin.
B31: Kehitysideoita saa laittaa alle

Sheet Pistetilanne
R2: KA | S2: Keskih
C3: =Tulokset!D2 | D3: =Tulokset!F2 | E3: =Tulokset!H2 | F3: =Tulokset!J2 | G3: =Tulokset!L2 | R3: =AVERAGE(C4:P4) | S3: =STDEV(C4:P4)
C4: =Tulokset!E131 | D4: =Tulokset!G131 | E4: =Tulokset!I131 | F4: =Tulokset!K131 | G4: =Tulokset!M131

Sheet Veikkaajien tilastot
B2: EM 2004 Portugal 1. GRE 2. POR | C2: MM 2006 Germany 1. ITA 2. FRA 3. GER | D2: EM 2008 AUS/SWI 1. SPA 2. GER | E2: MM 2010 S-Africa 1. SPA 2. NED 3. GER | F2: EM 2012 POL/UKR 1. SPA 2. ITA | G2: MM 2014 Brazil 1. GER 2. ARG 3. NED | H2: EM 2016 France 1. POR 2. FRA | I2: MM 2018 Russia 1. FRA 2. CRO 3. BEL | J2: EM 2020 1. ITA 2. ENG | K2: MM 2022 | L2: EM 2024 Germany
A3: Osallistujia | B3: 10 | C3: 24 | D3: 24 | E3: Ei | F3: 17 | G3: 16 | H3: 14 | I3: 20 | J3: 22 | K3: Ei
A4: Voittaja | B4: LariL | C4: Pele | D4: Tarhonen | E4: veikkausta | F4: Ville/Tolvanen | G4: Pele | H4: Jype | I4: Tarhonen | J4: Jukka | K4: veikkausta
A5: Kakkonen | B5: Jukka | C5: Kimmo/Hannu | D5: Kapa | G5: Aki | H5: Jere | I5: KimmoK | J5: Pete
A6: Kolmonen | B6: TimoS | D6: Tommi/Ile/Wade/Pele | F6: J.Saimen | G6: Ville/Tolvanen | H6: Saku | I6: Karri | J6: Pele
B9: Voitot | C9: 2. sijat | D9: 3. sijat
A10: Pele | B10: 2 | C10: 0 | D10: 2
A11: Tarhonen | B11: 2 | C11: 0 | D11: 0
A12: JukkaM | B12: 1 | C12: 1 | D12: 0
A13: Villarineste | B13: 1 | C13: 0 | D13: 1
A14: Tolvanen | B14: 1 | C14: 0 | D14: 1
A15: Jype | B15: 1 | C15: 0 | D15: 0
A16: LariL | B16: 1 | C16: 0 | D16: 0
A17: KimmoK | B17: 0 | C17: 2 | D17: 0
A18: HannuM | B18: 0 | C18: 1 | D18: 0
A19: Kapa | B19: 0 | C19: 1 | D19: 0
A20: AkiK | B20: 0 | C20: 1 | D20: 0
A21: Jermupisto | B21: 0 | C21: 1 | D21: 0
... A27: Karri | B27: 0 | C27: 0 | D27: 1
